Workbook

Sheet Read Me
A1: Purpose | B1: Regression pack for the Fund Transfer Service. Every case traces to a business rule in FundTransferRequirements.pdf (FTR-BRD-v3.2).
A2: Data notice | B2: All accounts, customers, beneficiaries, and results are fabricated for training. No production banking data is present.
A3: Suite version | B3: 3.2.0
A4: Cycle | B4: REG-2026-08-CYCLE-03
A5: Execution window | B5: 03-Aug-2026 to 07-Aug-2026
A6: Environment | B6: UAT2 - core banking simulator, OTP stub, sanction screening stub
A7: Test lead | B7: S. Menon
A9: SHEET GUIDE
A10: Test Cases | B10: 44 regression cases. Columns K to O are the only cells a tester should edit.
A11: Test Data | B11: Mock accounts, customers, and beneficiaries referenced by the cases.
A12: Execution Summary | B12: Formula-driven roll-up. Do not type values here.
A13: Traceability | B13: Business rule to test case coverage and pass rate. Formula-driven.
A15: EDITABLE CELLS (yellow fill)
A16: Test Cases!K | B16: Actual Result - free text
A17: Test Cases!L | B17: Status - Pass / Fail / Blocked / Not Run
A18: Test Cases!M | B18: Last Executed - date
A19: Test Cases!N | B19: Executed By - initials
A20: Test Cases!O | B20: Linked Defect - DEF-xxxx or blank
A22: EXAMPLE ROW FORMAT | B22: TC-FT-001 | BR-001 | Pass | 2026-08-03 | SM | (blank defect)

Sheet Test Cases
A1: TestCaseID | B1: Title | C1: RequirementID | D1: Module | E1: TestType | F1: Priority | G1: Preconditions | H1: TestSteps | I1: TestData | J1: ExpectedResult | K1: ActualResult | L1: Status | M1: LastExecuted | N1: ExecutedBy | O1: LinkedDefect | P1: Automated
A2: TC-FT-001 | B2: Single transfer at the exact limit of AED 50,000 | C2: BR-001 | D2: Transfer Core | E2: Boundary | F2: High | G2: Account ACC-1001 holds AED 120,000 and is ACTIVE. Beneficiary BEN-4471029 is ACTIVE. | H2: 1. Log in as CUST-70012. 2. Select ACC-1001 as source. 3. Enter 50000.00. 4. Confirm with OTP. | I2: amount=50000.00; currency=AED; beneficiary=BEN-4471029 | J2: Transfer is accepted. HTTP 201 with a transactionId in the format TRX-YYYYMMDD-XXXXXXXX. | K2: As expected. | L2: Pass | M2: 2026-08-03 | N2: SM | P2: Yes
A3: TC-FT-002 | B3: Single transfer one fils above the limit | C3: BR-001 | D3: Transfer Core | E3: Negative | F3: High | G3: Account ACC-1001 holds AED 120,000. | H3: 1. Enter 50000.01 as the amount. 2. Submit. | I3: amount=50000.01; currency=AED | J3: Rejected with HTTP 422 and code TRF-4001. Message names the AED 50,000 limit. | K3: As expected. | L3: Pass | M3: 2026-08-03 | N3: SM | P3: Yes
A4: TC-FT-003 | B4: Foreign currency amount converted before the limit check | C4: BR-001 | D4: Transfer Core | E4: Functional | F4: Medium | G4: Account ACC-1004 is USD enabled. Card rate USD 1 = AED 3.673. | H4: 1. Submit an international transfer of USD 20,000. 2. Observe the converted AED value in the error body. | I4: amount=20000.00; currency=USD; converted=73460.00 | J4: Rejected with TRF-4001 because the converted amount exceeds AED 50,000. | K4: As expected. | L4: Pass | M4: 2026-08-03 | N4: FQ | P4: Yes
A5: TC-FT-004 | B5: Daily cumulative total below the AED 100,000 ceiling | C5: BR-002 | D5: Limits Service | E5: Functional | F5: High | G5: CUST-70012 has transferred AED 95,000 today. | H5: 1. Submit a further transfer of AED 5,000. 2. Check dailyLimitRemaining in the response. | I5: consumedToday=95000.00; amount=5000.00 | J5: Accepted. dailyLimitRemaining equals 0.00. | K5: As expected. | L5: Pass | M5: 2026-08-04 | N5: SM | P5: Yes
A6: TC-FT-005 | B6: Daily limit breached by one fils | C6: BR-002 | D6: Limits Service | E6: Boundary | F6: High | G6: CUST-70012 has transferred AED 95,000 today. | H6: 1. Submit a transfer of AED 5,000.01. 2. Immediately submit four more transfers and compare dailyLimitRemaining. | I6: consumedToday=95000.00; amount=5000.01 | J6: Rejected with TRF-4002. dailyLimitRemaining is accurate in every response. | K6: Rejection is correct but dailyLimitRemaining repeats a stale value across consecutive responses. | L6: Fail | M6: 2026-08-04 | N6: SM | O6: DEF-1019 | P6: Yes
A7: TC-FT-006 | B7: Failed transfer does not consume the daily allowance | C7: BR-002 | D7: Limits Service | E7: Functional | F7: High | G7: Core banking stub configured to return a timeout. | H7: 1. Submit AED 30,000 and force TRF-5001. 2. Query /v1/limits/utilisation. | I7: amount=30000.00; forcedError=TRF-5001 | J7: consumedToday is unchanged by the failed transfer. | K7: As expected after the 2.6.0 fix. | L7: Pass | M7: 2026-08-04 | N7: FQ | P7: Yes
A8: TC-FT-007 | B8: Transfer equal to the available balance | C8: BR-003 | D8: Transfer Core | E8: Boundary | F8: High | G8: Account ACC-1002 holds an available balance of AED 10,000 with no fee on internal transfers. | H8: 1. Submit an internal transfer of AED 10,000. | I8: availableBalance=10000.00; amount=10000.00; fee=0.00 | J8: Accepted. The resulting balance is 0.00. | K8: As expected. | L8: Pass | M8: 2026-08-04 | N8: AH | P8: Yes
A9: TC-FT-008 | B9: Amount plus fee exceeds the available balance | C9: BR-003 | D9: Transfer Core | E9: Negative | F9: High | G9: Account ACC-1002 holds AED 10,000. International fee is AED 26.25. | H9: 1. Submit an international transfer of AED 10,000. | I9: availableBalance=10000.00; amount=10000.00; fee=26.25 | J9: Rejected with TRF-4003. | K9: As expected. | L9: Pass | M9: 2026-08-04 | N9: AH | P9: Yes
A10: TC-FT-009 | B10: Overdraft facility included in the available balance | C10: BR-003 | D10: Transfer Core | E10: Functional | F10: Medium | G10: Account ACC-1006 holds AED 1,000 with an approved overdraft of AED 5,000. | H10: 1. Submit a transfer of AED 6,000. | I10: ledgerBalance=1000.00; overdraftLimit=5000.00; amount=6000.00 | J10: Accepted. The account closes at minus AED 5,000 within the facility. | K10: As expected. | L10: Pass | M10: 2026-08-04 | N10: AH | P10: Yes
A11: TC-FT-010 | B11: Transfer to an ACTIVE beneficiary | C11: BR-004 | D11: Beneficiary Service | E11: Functional | F11: High | G11: BEN-4471029 is ACTIVE and was activated more than 30 minutes ago. | H11: 1. Submit a transfer of AED 1,500. | I11: beneficiary=BEN-4471029; status=ACTIVE | J11: Accepted. | K11: As expected. | L11: Pass | M11: 2026-08-03 | N11: SM | P11: Yes
A12: TC-FT-011 | B12: Transfer to a SUSPENDED beneficiary returns a generic message | C12: BR-004 | D12: Beneficiary Service | E12: Negative | F12: High | G12: BEN-5510388 is SUSPENDED. | H12: 1. Submit a transfer of AED 1,000. 2. Inspect the response body for internal wording. | I12: beneficiary=BEN-5510388; status=SUSPENDED | J12: Rejected with TRF-4004 and a generic message that does not name the suspension. | K12: As expected after the 3.2.0 fix. | L12: Pass | M12: 2026-08-05 | N12: SM | P12: Yes
A13: TC-FT-012 | B13: Beneficiary belonging to another customer | C13: BR-004 | D13: Beneficiary Service | E13: Security | F13: High | G13: BEN-6620144 belongs to CUST-70099. | H13: 1. Authenticate as CUST-70012. 2. Submit a transfer referencing BEN-6620144. | I13: beneficiary=BEN-6620144; owner=CUST-70099 | J13: Rejected with TRF-4004 so that beneficiary IDs cannot be enumerated. | K13: Returns HTTP 403 with a distinct body, which allows enumeration. | L13: Fail | M13: 2026-08-05 | N13: SM | O13: DEF-1011 | P13: Yes
A14: TC-FT-013 | B14: No OTP required at exactly AED 25,000 | C14: BR-005 | D14: OTP Service | E14: Boundary | F14: High | G14: Account ACC-1001 is funded. Fee applies but is excluded from the threshold. | H14: 1. Submit a transfer of AED 25,000.00. | I14: amount=25000.00; fee=1.05 | J14: Accepted without OTP. Status is COMPLETED, not AWAITING_OTP. | K14: As expected after the 3.1.0 fix. | L14: Pass | M14: 2026-08-05 | N14: FQ | P14: Yes
A15: TC-FT-014 | B15: OTP required one fils above the threshold | C15: BR-005 | D15: OTP Service | E15: Boundary | F15: High | G15: Account ACC-1001 is funded. | H15: 1. Submit a transfer of AED 25,000.01. 2. Observe the response status. | I15: amount=25000.01 | J15: HTTP 202 with status AWAITING_OTP, an otpReference, and attemptsRemaining of 3. | K15: As expected. | L15: Pass | M15: 2026-08-05 | N15: FQ | P15: Yes
A16: TC-FT-015 | B16: OTP expires after 180 seconds | C16: BR-005 | D16: OTP Service | E16: Negative | F16: High | G16: A transfer of AED 30,000 is in AWAITING_OTP. | H16: 1. Wait 181 seconds. 2. Submit the correct OTP. | I16: amount=30000.00; delaySeconds=181 | J16: Rejected with TRF-4007. | K16: As expected. | L16: Pass | M16: 2026-08-05 | N16: FQ | P16: Yes
A17: TC-FT-016 | B17: Transfer abandoned after three wrong OTP attempts | C17: BR-005 | D17: OTP Service | E17: Negative | F17: High | G17: A transfer of AED 30,000 is in AWAITING_OTP. | H17: 1. Submit a wrong OTP three times. 2. Submit the correct OTP. | I17: wrongAttempts=3 | J17: Status becomes ABANDONED. The correct OTP is refused with attemptsRemaining of 0. | K17: As expected after the 3.0.0 fix. | L17: Pass | M17: 2026-08-05 | N17: FQ | P17: Yes
A18: TC-FT-017 | B18: Zero amount rejected | C18: BR-006 | D18: API Gateway | E18: Negative | F18: High | G18: Any funded account. | H18: 1. Submit a transfer with an amount of 0. | I18: amount=0 | J18: Rejected with HTTP 400 and TRF-4008. No downstream call is made. | K18: As expected. | L18: Pass | M18: 2026-08-03 | N18: AH | P18: Yes
A19: TC-FT-018 | B19: Negative amount rejected | C19: BR-006 | D19: API Gateway | E19: Negative | F19: High | G19: Any funded account. | H19: 1. Submit a transfer with an amount of -100. | I19: amount=-100 | J19: Rejected with HTTP 400 and TRF-4008. | K19: As expected. | L19: Pass | M19: 2026-08-03 | N19: AH | P19: Yes
A20: TC-FT-019 | B20: Amount with three decimal places rejected | C20: BR-006 | D20: API Gateway | E20: Negative | F20: Medium | G20: Any funded account. | H20: 1. Submit a transfer with an amount of 100.126. | I20: amount=100.126 | J20: Rejected with TRF-4008. | K20: Amount is silently rounded to 100.13 and the transfer proceeds. | L20: Fail | M20: 2026-08-03 | N20: AH | O20: DEF-1018 | P20: Yes
A21: TC-FT-020 | B21: Identical source and destination rejected | C21: BR-007 | D21: Transfer Core | E21: Negative | F21: High | G21: ACC-1001 is registered as its own beneficiary in the test fixture. | H21: 1. Submit a transfer where source and destination IBANs match. | I21: source=AE070331234567890123456; destination=AE070331234567890123456 | J21: Rejected with TRF-4009. | K21: As expected. | L21: Pass | M21: 2026-08-04 | N21: SM | P21: Yes
A22: TC-FT-021 | B22: IBAN normalisation before the identity check | C22: BR-007 | D22: Transfer Core | E22: Negative | F22: Medium | G22: Same as TC-FT-020 but the source IBAN is entered with spaces. | H22: 1. Submit with source "AE07 0331 2345 6789 0123 456" and an identical destination without spaces. | I22: source contains spaces; destination does not | J22: Both values are normalised and the request is rejected with TRF-4009. | K22: As expected after the 2.6.0 fix. | L22: Pass | M22: 2026-08-04 | N22: SM | P22: Yes
A23: TC-FT-022 | B23: Transfer in a currency enabled on the account | C23: BR-008 | D23: Transfer Core | E23: Functional | F23: High | G23: ACC-1004 supports AED and USD. | H23: 1. Submit a USD 500 transfer from ACC-1004. | I23: currency=USD; supportedCurrencies=[AED,USD] | J23: Accepted. | K23: As expected. | L23: Pass | M23: 2026-08-06 | N23: FQ | P23: Yes
A24: TC-FT-023 | B24: Transfer in a currency not enabled on the account | C24: BR-008 | D24: Transfer Core | E24: Negative | F24: High | G24: ACC-1001 supports AED only. | H24: 1. Submit a JPY 10,000 transfer from ACC-1001. | I24: currency=JPY; supportedCurrencies=[AED] | J24: Rejected with TRF-4010. | K24: As expected. | L24: Pass | M24: 2026-08-06 | N24: FQ | P24: Yes
A25: TC-FT-024 | B25: Frozen source account cannot transfer | C25: BR-009 | D25: Transfer Core | E25: Negative | F25: High | G25: ACC-1005 carries status FRZ. | H25: 1. Submit a transfer of AED 1,000 from ACC-1005. | I25: accountStatus=FRZ | J25: Rejected with HTTP 403 and TRF-4011. The message is generic. | K25: As expected. | L25: Pass | M25: 2026-08-06 | N25: AH | P25: Yes
A26: TC-FT-025 | B26: Frozen internal destination account cannot receive | C26: BR-009 | D26: Transfer Core | E26: Negative | F26: Medium | G26: Beneficiary BEN-7730255 maps to internal account ACC-1005 with status FRZ. | H26: 1. Submit a transfer of AED 1,000 to BEN-7730255. | I26: destinationStatus=FRZ | J26: Rejected with TRF-4011. | K26: As expected. | L26: Pass | M26: 2026-08-06 | N26: AH | P26: Yes
A27: TC-FT-026 | B27: Transaction ID format and presence | C27: BR-010 | D27: Transfer Core | E27: Functional | F27: High | G27: Any successful transfer. | H27: 1. Submit a transfer of AED 500. 2. Validate the transactionId against ^TRX-[0-9]{8}-[A-Z0-9]{8}$. 3. Check the Location header. | I27: amount=500.00 | J27: The identifier matches the pattern and appears in both the body and the Location header. | K27: As expected. | L27: Pass | M27: 2026-08-03 | N27: KI | P27: Yes
A28: TC-FT-027 | B28: Transaction ID immutable after reversal | C28: BR-010 | D28: Transfer Core | E28: Functional | F28: Medium | G28: A completed transfer TRX-20260803-4KD91MZQ exists. | H28: 1. Reverse the transfer. 2. Retrieve both records. | I28: originalTransactionId=TRX-20260803-4KD91MZQ | J28: The original identifier is unchanged and the reversal carries a new identifier referencing it. | K28: As expected. | L28: Pass | M28: 2026-08-03 | N28: KI | P28: Yes
A29: TC-FT-028 | B29: Idempotent replay returns the original transfer | C29: BR-011 | D29: API Gateway | E29: Functional | F29: High | G29: No prior request with key K-8814. | H29: 1. POST a transfer of AED 1,000 with key K-8814. 2. Repeat the identical request. | I29: idempotencyKey=K-8814; amount=1000.00 both times | J29: The second call returns HTTP 200 with the original transactionId and no second debit occurs. | K29: As expected. | L29: Pass | M29: 2026-08-06 | N29: MR | P29: Yes
A30: TC-FT-029 | B30: New beneficiary limited to AED 5,000 inside the cooling window | C30: BR-012 | D30: Beneficiary Service | E30: Boundary | F30: High | G30: BEN-8840311 was activated 10 minutes ago. | H30: 1. Submit a transfer of AED 5,000. 2. Submit a transfer of AED 5,001. | I30: activatedAt = now minus 10 minutes | J30: The first is accepted; the second is rejected with TRF-4013. | K30: As expected. | L30: Pass | M30: 2026-08-07 | N30: SM | P30: Yes
A31: TC-FT-030 | B31: Value date shifts after the 21:00 GST cut-off | C31: BR-013 | D31: Scheduling | E31: Functional | F31: Medium | G31: System clock set to 21:01 GST on a business day. | H31: 1. Submit a domestic transfer of AED 2,000. 2. Read valueDate in the response. | I31: submittedAt=21:01 GST | J31: valueDate is the next business day and the customer is shown the shift before confirming. | K31: As expected. | L31: Pass | M31: 2026-08-07 | N31: KI | P31: Yes
A32: TC-FT-031 | B32: Daily counter resets at 00:00 Gulf Standard Time | C32: BR-002 | D32: Limits Service | E32: Regression | F32: High | G32: CUST-70012 consumed the full AED 100,000 allowance yesterday. | H32: 1. Advance the clock to 00:00:01 GST. 2. Query /v1/limits/utilisation. 3. Submit a transfer of AED 10,000. | I32: windowResetsAt=00:00:00+04:00 | J32: consumedToday reads 0.00 and the transfer is accepted. | K32: As expected after the 3.2.0 fix. | L32: Pass | M32: 2026-08-04 | N32: MR | P32: Yes
A33: TC-FT-032 | B33: Concurrent transfers cannot overdraw the account | C33: BR-003 | D33: Transfer Core | E33: Concurrency | F33: High | G33: ACC-1002 holds AED 10,000. | H33: 1. Fire two transfers of AED 6,000 within 50 ms using distinct idempotency keys. 2. Check the closing balance. | I33: threads=2; amount=6000.00 each | J33: Exactly one succeeds; the other is rejected with TRF-4003. The balance never goes negative. | K33: As expected after the 2.5.0 fix. | L33: Pass | M33: 2026-08-06 | N33: KI | P33: Yes
A34: TC-FT-033 | B34: OTP resend does not reset the attempt counter | C34: BR-005 | D34: OTP Service | E34: Security | F34: High | G34: A transfer of AED 30,000 is in AWAITING_OTP with two failed attempts. | H34: 1. Request an OTP resend. 2. Read attemptsRemaining. | I34: failedAttempts=2; resendCount=1 | J34: attemptsRemaining stays at 1. | K34: attemptsRemaining resets to 3, permitting nine guesses across two resends. | L34: Fail | M34: 2026-08-07 | N34: SM | O34: DEF-1020 | P34: Yes
A35: TC-FT-034 | B35: Lower-case currency code normalised | C35: BR-008 | D35: Transfer Core | E35: Regression | F35: Low | G35: ACC-1001 supports AED. | H35: 1. Submit a transfer with currency set to "aed". | I35: currency=aed | J35: The value is normalised to AED and the transfer is accepted. | K35: As expected after the 3.0.0 fix. | L35: Pass | M35: 2026-08-06 | N35: FQ | P35: Yes
A36: TC-FT-035 | B36: Freeze applied between OTP issue and OTP verification | C36: BR-009 | D36: Transfer Core | E36: Regression | F36: High | G36: A transfer of AED 30,000 is in AWAITING_OTP on ACC-1001. | H36: 1. Freeze ACC-1001. 2. Submit the correct OTP. | I36: accountStatus changes to FRZ mid-flow | J36: Rejected with TRF-4011 because the rule chain re-runs at posting time. | K36: As expected after the 3.0.0 fix. | L36: Pass | M36: 2026-08-07 | N36: AH | P36: Yes
A37: TC-FT-036 | B37: Transaction ID uniqueness under load | C37: BR-010 | D37: Transfer Core | E37: Performance | F37: High | G37: Load harness configured for 400 transfers per second. | H37: 1. Run for 10 minutes. 2. Group the transaction IDs and count duplicates. | I37: targetTps=400; durationMinutes=10 | J37: Zero duplicate identifiers across the run. | K37: As expected after the 2.6.0 fix. | L37: Pass | M37: 2026-08-07 | N37: KI | P37: Yes
A38: TC-FT-037 | B38: Idempotency key replayed with a different body | C38: BR-011 | D38: API Gateway | E38: Negative | F38: High | G38: A transfer of AED 1,000 was created with key K-9021. | H38: 1. POST a transfer of AED 9,000 reusing key K-9021. | I38: idempotencyKey=K-9021; amount=9000.00 | J38: Rejected with HTTP 409 and TRF-4012. | K38: Returns HTTP 200 with the AED 1,000 transfer, so the customer believes AED 9,000 was sent. | L38: Fail | M38: 2026-08-06 | N38: MR | O38: DEF-1006 | P38: Yes
A39: TC-FT-038 | B39: Idempotency key expires after 24 hours | C39: BR-011 | D39: API Gateway | E39: Functional | F39: Medium | G39: Key K-7702 was used 25 hours ago. | H39: 1. Replay the identical request with key K-7702. | I39: keyAgeHours=25 | J39: Treated as a new request and a second transfer is created. | K39: As expected. | L39: Pass | M39: 2026-08-06 | N39: MR | P39: Yes
A40: TC-FT-039 | B40: Cooling period measured from activation, not creation | C40: BR-012 | D40: Beneficiary Service | E40: Regression | F40: High | G40: BEN-8840311 was created 40 minutes ago and activated 2 minutes ago. | H40: 1. Submit a transfer of AED 20,000. | I40: createdAt = now minus 40 min; activatedAt = now minus 2 min | J40: Rejected with TRF-4013. | K40: Accepted, because the window is counted from creation. | L40: Fail | M40: 2026-08-07 | N40: SM | O40: DEF-1015 | P40: Yes
...

Sheet Test Data
A1: MOCK TEST DATA - fabricated for training. No production banking data.
A3: ACCOUNTS
A4: AccountRef | B4: IBAN | C4: CustomerID | D4: AccountType | E4: Status | F4: LedgerBalanceAED | G4: HoldAED | H4: OverdraftAED | I4: SupportedCurrencies | J4: Notes
A5: ACC-1001 | B5: AE070331234567890123456 | C5: CUST-70012 | D5: Current | E5: ACTIVE | F5: 120000 | G5: 0 | H5: 0 | I5: AED | J5: Primary happy-path account
A6: ACC-1002 | B6: AE480260000012345678901 | C6: CUST-70012 | D6: Savings | E6: ACTIVE | F6: 10000 | G6: 0 | H6: 0 | I6: AED | J6: Used for balance boundary cases
A7: ACC-1003 | B7: AE900500000098765432109 | C7: CUST-70034 | D7: Current | E7: DORMANT | F7: 8500 | G7: 0 | H7: 0 | I7: AED | J7: Dormant account fixture
A8: ACC-1004 | B8: AE120345000011122233344 | C8: CUST-70012 | D8: Foreign Currency | E8: ACTIVE | F8: 55000 | G8: 0 | H8: 0 | I8: AED,USD,EUR | J8: Multi-currency fixture
A9: ACC-1005 | B9: AE660410000055566677788 | C9: CUST-70057 | D9: Current | E9: FRZ | F9: 30000 | G9: 0 | H9: 0 | I9: AED | J9: Compliance freeze fixture
A10: ACC-1006 | B10: AE220620000099988877766 | C10: CUST-70034 | D10: Current | E10: ACTIVE | F10: 1000 | G10: 0 | H10: 5000 | I10: AED | J10: Overdraft fixture
A11: ACC-1007 | B11: AE330710000044455566677 | C11: CUST-70099 | D11: Current | E11: ACTIVE | F11: 250000 | G11: 12000 | H11: 0 | I11: AED,USD | J11: Hold amount fixture
A13: AVAILABLE BALANCE CHECK (formula, per BR-003: ledger - hold + overdraft)
A14: AccountRef | B14: AvailableBalanceAED
A15: ACC-1001 | B15: =F5-G5+H5 -> 120000
A16: ACC-1002 | B16: =F6-G6+H6 -> 10000
A17: ACC-1003 | B17: =F7-G7+H7 -> 8500
A18: ACC-1004 | B18: =F8-G8+H8 -> 55000
A19: ACC-1005 | B19: =F9-G9+H9 -> 30000
A20: ACC-1006 | B20: =F10-G10+H10 -> 6000
A21: ACC-1007 | B21: =F11-G11+H11 -> 238000
A24: BENEFICIARIES
A25: BeneficiaryID | B25: Nickname | C25: OwnerCustomerID | D25: IBAN | E25: BankCode | F25: Type | G25: Currency | H25: Status | I25: ActivatedAt | J25: Notes
A26: BEN-4471029 | B26: Ahmed - Salary | C26: CUST-70012 | D26: AE480260000012345678901 | E26: EBILAEAD | F26: DOMESTIC | G26: AED | H26: ACTIVE | I26: 2025-11-02T11:33:00Z | J26: Standard happy path
A27: BEN-9982117 | B27: University Fees | C27: CUST-70012 | D27: GB29NWBK60161331926819 | E27: NWBKGB2L | F27: INTERNATIONAL | G27: USD | H27: ACTIVE | I27: 2026-01-18T08:15:00Z | J27: International fixture
A28: BEN-5510388 | B28: Landlord | C28: CUST-70012 | D28: AE900500000098765432109 | E28: ADCBAEAA | F28: DOMESTIC | G28: AED | H28: SUSPENDED | I28: 2026-03-09T13:50:00Z | J28: BR-004 negative fixture
A29: BEN-6620144 | B29: Foreign owner | C29: CUST-70099 | D29: AE120345000011122233344 | E29: EBILAEAD | F29: DOMESTIC | G29: AED | H29: ACTIVE | I29: 2026-02-20T09:00:00Z | J29: Ownership security fixture
A30: BEN-7730255 | B30: Frozen internal | C30: CUST-70012 | D30: AE660410000055566677788 | E30: EBILAEAD | F30: INTERNAL | G30: AED | H30: ACTIVE | I30: 2025-05-14T06:30:00Z | J30: Maps to frozen ACC-1005
A31: BEN-8840311 | B31: Newly added | C31: CUST-70012 | D31: AE220620000099988877766 | E31: EBILAEAD | F31: DOMESTIC | G31: AED | H31: ACTIVE | I31: dynamic - now minus 2 minutes | J31: BR-012 cooling period fixture
A32: BEN-9950422 | B32: Pending payee | C32: CUST-70012 | D32: AE330710000044455566677 | E32: ADCBAEAA | F32: DOMESTIC | G32: AED | H32: PENDING | J32: BR-004 negative fixture
A35: CUSTOMERS
A36: CustomerID | B36: MockName | C36: Segment | D36: RegisteredMobile | E36: DailyLimitAED | F36: SingleLimitAED | G36: OtpThresholdAED | H36: Notes
A37: CUST-70012 | B37: Test Customer Alpha | C37: Retail | D37: +9715000000001 | E37: 100000 | F37: 50000 | G37: 25000 | H37: Main regression customer
A38: CUST-70034 | B38: Test Customer Bravo | C38: Retail | D38: +9715000000002 | E38: 100000 | F38: 50000 | G38: 25000 | H38: Overdraft and dormant fixtures
A39: CUST-70057 | B39: Test Customer Charlie | C39: Retail | D39: +9715000000003 | E39: 100000 | F39: 50000 | G39: 25000 | H39: Frozen account fixture
A40: CUST-70099 | B40: Test Customer Delta | C40: Priority | D40: +9715000000004 | E40: 300000 | F40: 150000 | G40: 25000 | H40: Higher-limit segment fixture

Sheet Execution Summary
A1: Execution Summary - REG-2026-08-CYCLE-03 (formula driven, do not type values)
A2: Source: 'Test Cases' sheet, rows 2 to 45. Environment UAT2. Suite version 3.2.0.
A4: Metric | B4: Value
A5: Total test cases | B5: =COUNTA('Test Cases'!A2:A45) -> 44
A6: Passed | B6: =COUNTIF('Test Cases'!L2:L45,"Pass") -> 35
A7: Failed | B7: =COUNTIF('Test Cases'!L2:L45,"Fail") -> 9
A8: Blocked | B8: =COUNTIF('Test Cases'!L2:L45,"Blocked") -> 0
A9: Not Run | B9: =COUNTIF('Test Cases'!L2:L45,"Not Run") -> 0
A10: Automated | B10: =COUNTIF('Test Cases'!P2:P45,"Yes") -> 42
A11: Manual | B11: =COUNTIF('Test Cases'!P2:P45,"No") -> 2
A12: Distinct defects raised | B12: =SUMPRODUCT((('Test Cases'!O2:O45)<>"")*1) -> 9
A13: Pass rate | B13: =IFERROR(B6/B5,0) -> 0.79545455
A16: BY PRIORITY
A17: Priority | B17: Total | C17: Passed | D17: Failed
A18: High | B18: =COUNTIF('Test Cases'!F2:F45,A18) -> 34 | C18: =COUNTIFS('Test Cases'!F2:F45,A18,'Test Cases'!L2:L45,"Pass") -> 27 | D18: =COUNTIFS('Test Cases'!F2:F45,A18,'Test Cases'!L2:L45,"Fail") -> 7
A19: Medium | B19: =COUNTIF('Test Cases'!F2:F45,A19) -> 9 | C19: =COUNTIFS('Test Cases'!F2:F45,A19,'Test Cases'!L2:L45,"Pass") -> 7 | D19: =COUNTIFS('Test Cases'!F2:F45,A19,'Test Cases'!L2:L45,"Fail") -> 2
A20: Low | B20: =COUNTIF('Test Cases'!F2:F45,A20) -> 1 | C20: =COUNTIFS('Test Cases'!F2:F45,A20,'Test Cases'!L2:L45,"Pass") -> 1 | D20: =COUNTIFS('Test Cases'!F2:F45,A20,'Test Cases'!L2:L45,"Fail") -> 0
A23: BY MODULE
A24: Module | B24: Total | C24: Passed | D24: Failed
A25: Transfer Core | B25: =COUNTIF('Test Cases'!D2:D45,A25) -> 18 | C25: =COUNTIFS('Test Cases'!D2:D45,A25,'Test Cases'!L2:L45,"Pass") -> 18 | D25: =COUNTIFS('Test Cases'!D2:D45,A25,'Test Cases'!L2:L45,"Fail") -> 0
A26: OTP Service | B26: =COUNTIF('Test Cases'!D2:D45,A26) -> 5 | C26: =COUNTIFS('Test Cases'!D2:D45,A26,'Test Cases'!L2:L45,"Pass") -> 4 | D26: =COUNTIFS('Test Cases'!D2:D45,A26,'Test Cases'!L2:L45,"Fail") -> 1
A27: Limits Service | B27: =COUNTIF('Test Cases'!D2:D45,A27) -> 4 | C27: =COUNTIFS('Test Cases'!D2:D45,A27,'Test Cases'!L2:L45,"Pass") -> 3 | D27: =COUNTIFS('Test Cases'!D2:D45,A27,'Test Cases'!L2:L45,"Fail") -> 1
A28: Beneficiary Service | B28: =COUNTIF('Test Cases'!D2:D45,A28) -> 5 | C28: =COUNTIFS('Test Cases'!D2:D45,A28,'Test Cases'!L2:L45,"Pass") -> 3 | D28: =COUNTIFS('Test Cases'!D2:D45,A28,'Test Cases'!L2:L45,"Fail") -> 2
A29: API Gateway | B29: =COUNTIF('Test Cases'!D2:D45,A29) -> 6 | C29: =COUNTIFS('Test Cases'!D2:D45,A29,'Test Cases'!L2:L45,"Pass") -> 4 | D29: =COUNTIFS('Test Cases'!D2:D45,A29,'Test Cases'!L2:L45,"Fail") -> 2
A30: Compliance Integration | B30: =COUNTIF('Test Cases'!D2:D45,A30) -> 2 | C30: =COUNTIFS('Test Cases'!D2:D45,A30,'Test Cases'!L2:L45,"Pass") -> 1 | D30: =COUNTIFS('Test Cases'!D2:D45,A30,'Test Cases'!L2:L45,"Fail") -> 1
A31: Scheduling | B31: =COUNTIF('Test Cases'!D2:D45,A31) -> 2 | C31: =COUNTIFS('Test Cases'!D2:D45,A31,'Test Cases'!L2:L45,"Pass") -> 1 | D31: =COUNTIFS('Test Cases'!D2:D45,A31,'Test Cases'!L2:L45,"Fail") -> 1
A32: Audit | B32: =COUNTIF('Test Cases'!D2:D45,A32) -> 2 | C32: =COUNTIFS('Test Cases'!D2:D45,A32,'Test Cases'!L2:L45,"Pass") -> 1 | D32: =COUNTIFS('Test Cases'!D2:D45,A32,'Test Cases'!L2:L45,"Fail") -> 1

Sheet Traceability
A1: Requirement to Test Coverage - FTR-BRD-v3.2
A2: Counts are formulas over the 'Test Cases' sheet. Defect counts are maintained manually against KnownDefects.csv.
A4: RequirementID | B4: Rule Summary | C4: TestCaseCount | D4: Passed | E4: Failed | F4: CoverageStatus | G4: OpenDefects
A5: BR-001 | B5: Maximum single transfer is AED 50,000 | C5: =COUNTIF('Test Cases'!C2:C45,A5) -> 3 | D5: =COUNTIFS('Test Cases'!C2:C45,A5,'Test Cases'!L2:L45,"Pass") -> 3 | E5: =COUNTIFS('Test Cases'!C2:C45,A5,'Test Cases'!L2:L45,"Fail") -> 0 | F5: =IF(C5=0,"NOT COVERED",IF(E5>0,"COVERED - DEFECTS OPEN","COVERED - PASSING")) -> COVERED - PASSING | G5: -
A6: BR-002 | B6: Maximum daily transfer amount is AED 100,000 | C6: =COUNTIF('Test Cases'!C2:C45,A6) -> 4 | D6: =COUNTIFS('Test Cases'!C2:C45,A6,'Test Cases'!L2:L45,"Pass") -> 3 | E6: =COUNTIFS('Test Cases'!C2:C45,A6,'Test Cases'!L2:L45,"Fail") -> 1 | F6: =IF(C6=0,"NOT COVERED",IF(E6>0,"COVERED - DEFECTS OPEN","COVERED - PASSING")) -> COVERED - DEFECTS OPEN | G6: DEF-1019
A7: BR-003 | B7: Cannot transfer more than available balance | C7: =COUNTIF('Test Cases'!C2:C45,A7) -> 4 | D7: =COUNTIFS('Test Cases'!C2:C45,A7,'Test Cases'!L2:L45,"Pass") -> 4 | E7: =COUNTIFS('Test Cases'!C2:C45,A7,'Test Cases'!L2:L45,"Fail") -> 0 | F7: =IF(C7=0,"NOT COVERED",IF(E7>0,"COVERED - DEFECTS OPEN","COVERED - PASSING")) -> COVERED - PASSING | G7: -
A8: BR-004 | B8: Beneficiary status must be ACTIVE | C8: =COUNTIF('Test Cases'!C2:C45,A8) -> 3 | D8: =COUNTIFS('Test Cases'!C2:C45,A8,'Test Cases'!L2:L45,"Pass") -> 2 | E8: =COUNTIFS('Test Cases'!C2:C45,A8,'Test Cases'!L2:L45,"Fail") -> 1 | F8: =IF(C8=0,"NOT COVERED",IF(E8>0,"COVERED - DEFECTS OPEN","COVERED - PASSING")) -> COVERED - DEFECTS OPEN | G8: DEF-1011
A9: BR-005 | B9: Transfers above AED 25,000 require OTP | C9: =COUNTIF('Test Cases'!C2:C45,A9) -> 5 | D9: =COUNTIFS('Test Cases'!C2:C45,A9,'Test Cases'!L2:L45,"Pass") -> 4 | E9: =COUNTIFS('Test Cases'!C2:C45,A9,'Test Cases'!L2:L45,"Fail") -> 1 | F9: =IF(C9=0,"NOT COVERED",IF(E9>0,"COVERED - DEFECTS OPEN","COVERED - PASSING")) -> COVERED - DEFECTS OPEN | G9: DEF-1020
A10: BR-006 | B10: Amount must be greater than zero | C10: =COUNTIF('Test Cases'!C2:C45,A10) -> 3 | D10: =COUNTIFS('Test Cases'!C2:C45,A10,'Test Cases'!L2:L45,"Pass") -> 2 | E10: =COUNTIFS('Test Cases'!C2:C45,A10,'Test Cases'!L2:L45,"Fail") -> 1 | F10: =IF(C10=0,"NOT COVERED",IF(E10>0,"COVERED - DEFECTS OPEN","COVERED - PASSING")) -> COVERED - DEFECTS OPEN | G10: DEF-1018
A11: BR-007 | B11: Source and destination cannot be identical | C11: =COUNTIF('Test Cases'!C2:C45,A11) -> 2 | D11: =COUNTIFS('Test Cases'!C2:C45,A11,'Test Cases'!L2:L45,"Pass") -> 2 | E11: =COUNTIFS('Test Cases'!C2:C45,A11,'Test Cases'!L2:L45,"Fail") -> 0 | F11: =IF(C11=0,"NOT COVERED",IF(E11>0,"COVERED - DEFECTS OPEN","COVERED - PASSING")) -> COVERED - PASSING | G11: -
A12: BR-008 | B12: Currency must be supported by the account | C12: =COUNTIF('Test Cases'!C2:C45,A12) -> 3 | D12: =COUNTIFS('Test Cases'!C2:C45,A12,'Test Cases'!L2:L45,"Pass") -> 3 | E12: =COUNTIFS('Test Cases'!C2:C45,A12,'Test Cases'!L2:L45,"Fail") -> 0 | F12: =IF(C12=0,"NOT COVERED",IF(E12>0,"COVERED - DEFECTS OPEN","COVERED - PASSING")) -> COVERED - PASSING | G12: -
A13: BR-009 | B13: Frozen accounts cannot initiate transfers | C13: =COUNTIF('Test Cases'!C2:C45,A13) -> 3 | D13: =COUNTIFS('Test Cases'!C2:C45,A13,'Test Cases'!L2:L45,"Pass") -> 3 | E13: =COUNTIFS('Test Cases'!C2:C45,A13,'Test Cases'!L2:L45,"Fail") -> 0 | F13: =IF(C13=0,"NOT COVERED",IF(E13>0,"COVERED - DEFECTS OPEN","COVERED - PASSING")) -> COVERED - PASSING | G13: -
A14: BR-010 | B14: Successful transfer generates a unique transaction ID | C14: =COUNTIF('Test Cases'!C2:C45,A14) -> 3 | D14: =COUNTIFS('Test Cases'!C2:C45,A14,'Test Cases'!L2:L45,"Pass") -> 3 | E14: =COUNTIFS('Test Cases'!C2:C45,A14,'Test Cases'!L2:L45,"Fail") -> 0 | F14: =IF(C14=0,"NOT COVERED",IF(E14>0,"COVERED - DEFECTS OPEN","COVERED - PASSING")) -> COVERED - PASSING | G14: -
A15: BR-011 | B15: Requests must be idempotent for 24 hours | C15: =COUNTIF('Test Cases'!C2:C45,A15) -> 3 | D15: =COUNTIFS('Test Cases'!C2:C45,A15,'Test Cases'!L2:L45,"Pass") -> 2 | E15: =COUNTIFS('Test Cases'!C2:C45,A15,'Test Cases'!L2:L45,"Fail") -> 1 | F15: =IF(C15=0,"NOT COVERED",IF(E15>0,"COVERED - DEFECTS OPEN","COVERED - PASSING")) -> COVERED - DEFECTS OPEN | G15: DEF-1006
A16: BR-012 | B16: New beneficiary 30-minute cooling period | C16: =COUNTIF('Test Cases'!C2:C45,A16) -> 2 | D16: =COUNTIFS('Test Cases'!C2:C45,A16,'Test Cases'!L2:L45,"Pass") -> 1 | E16: =COUNTIFS('Test Cases'!C2:C45,A16,'Test Cases'!L2:L45,"Fail") -> 1 | F16: =IF(C16=0,"NOT COVERED",IF(E16>0,"COVERED - DEFECTS OPEN","COVERED - PASSING")) -> COVERED - DEFECTS OPEN | G16: DEF-1015
A17: BR-013 | B17: Same-day cut-off at 21:00 GST | C17: =COUNTIF('Test Cases'!C2:C45,A17) -> 2 | D17: =COUNTIFS('Test Cases'!C2:C45,A17,'Test Cases'!L2:L45,"Pass") -> 1 | E17: =COUNTIFS('Test Cases'!C2:C45,A17,'Test Cases'!L2:L45,"Fail") -> 1 | F17: =IF(C17=0,"NOT COVERED",IF(E17>0,"COVERED - DEFECTS OPEN","COVERED - PASSING")) -> COVERED - DEFECTS OPEN | G17: DEF-1012
A18: BR-014 | B18: Sanction screening at AED 20,000 and above | C18: =COUNTIF('Test Cases'!C2:C45,A18) -> 2 | D18: =COUNTIFS('Test Cases'!C2:C45,A18,'Test Cases'!L2:L45,"Pass") -> 1 | E18: =COUNTIFS('Test Cases'!C2:C45,A18,'Test Cases'!L2:L45,"Fail") -> 1 | F18: =IF(C18=0,"NOT COVERED",IF(E18>0,"COVERED - DEFECTS OPEN","COVERED - PASSING")) -> COVERED - DEFECTS OPEN | G18: DEF-1017
A19: BR-015 | B19: Audit record for every transfer attempt | C19: =COUNTIF('Test Cases'!C2:C45,A19) -> 2 | D19: =COUNTIFS('Test Cases'!C2:C45,A19,'Test Cases'!L2:L45,"Pass") -> 1 | E19: =COUNTIFS('Test Cases'!C2:C45,A19,'Test Cases'!L2:L45,"Fail") -> 1 | F19: =IF(C19=0,"NOT COVERED",IF(E19>0,"COVERED - DEFECTS OPEN","COVERED - PASSING")) -> COVERED - DEFECTS OPEN | G19: DEF-1014
A21: TOTAL | C21: =SUM(C5:C19) -> 44 | D21: =SUM(D5:D19) -> 35 | E21: =SUM(E5:E19) -> 9
